<?xml version="1.0"?>
<robot name="my_robot">
    <!-- 底盘 -->
    <link name="base_link">
        <inertial>
            <mass value="1.0"/>
            <inertia ixx="0.1" ixy="0.0" ixz="0.0" iyy="0.1" iyz="0.0" izz="0.1"/>
        </inertial>
        <visual>
            <geometry>
                <cylinder length="0.2" radius="0.3"/>
            </geometry>
            <material name="yellow">
                <color rgba="1.0 1.0 0.0 1.0"/>
            </material>
        </visual>
        <collision>
            <geometry>
                <cylinder length="0.2" radius="0.3"/>
            </geometry>
        </collision>
    </link>

    <!-- 左轮子 -->
    <link name="left_wheel_link">
        <inertial>
            <mass value="0.1"/>
            <inertia ixx="0.001" ixy="0.0" ixz="0.0" iyy="0.005" iyz="0.0" izz="0.005"/>
        </inertial>
        <visual>
            <geometry>
                <cylinder length="0.05" radius="0.1"/>
            </geometry>
            <material name="red">
                <color rgba="1.0 0.0 0.0 1.0"/>
            </material>
        </visual>
        <collision>
            <geometry>
                <cylinder length="0.05" radius="0.1"/>
            </geometry>
        </collision>
    </link>
    <joint name="left_wheel_joint" type="continuous">
        <parent link="base_link"/>
        <child link="left_wheel_link"/>
        <origin xyz="0.0 -0.3 -0.1" rpy="1.5708 0.0 0.0"/>
        <axis xyz="0 1 0"/>
        <!-- 移除了limit标签，continuous关节不需要限制 -->
    </joint>

    <!-- 右轮子 -->
    <link name="right_wheel_link">
        <inertial>
            <mass value="0.1"/>
            <inertia ixx="0.001" ixy="0.0" ixz="0.0" iyy="0.005" iyz="0.0" izz="0.005"/>
        </inertial>
        <visual>
            <geometry>
                <cylinder length="0.05" radius="0.1"/>
            </geometry>
            <material name="red">
                <color rgba="1.0 0.0 0.0 1.0"/>
            </material>
        </visual>
        <collision>
            <geometry>
                <cylinder length="0.05" radius="0.1"/>
            </geometry>
        </collision>
    </link>
    <joint name="right_wheel_joint" type="continuous">
        <parent link="base_link"/>
        <child link="right_wheel_link"/>
        <origin xyz="0.0 0.3 -0.1" rpy="1.5708 0.0 0.0"/>
        <axis xyz="0 1 0"/>
        <!-- 移除了limit标签，continuous关节不需要限制 -->
    </joint>

    <!-- 中间支柱 -->
    <link name="pillar_link">
        <inertial>
            <mass value="0.5"/>
            <inertia ixx="0.05" ixy="0.0" ixz="0.0" iyy="0.05" iyz="0.0" izz="0.05"/>
        </inertial>
        <visual>
            <geometry>
                <cylinder length="0.5" radius="0.05"/>
            </geometry>
            <material name="white">
                <color rgba="1.0 1.0 1.0 1.0"/>
            </material>
        </visual>
        <collision>
            <geometry>
                <cylinder length="0.5" radius="0.05"/>
            </geometry>
        </collision>
    </link>
    <joint name="pillar_joint" type="fixed">
        <parent link="base_link"/>
        <child link="pillar_link"/>
        <origin xyz="0.0 0.0 0.1" rpy="0.0 0.0 0.0"/>
    </joint>

    <!-- 顶部黑色部件 -->
    <link name="top_link">
        <inertial>
            <mass value="0.3"/>
            <inertia ixx="0.03" ixy="0.0" ixz="0.0" iyy="0.03" iyz="0.0" izz="0.03"/>
        </inertial>
        <visual>
            <geometry>
                <cylinder length="0.2" radius="0.15"/>
            </geometry>
            <material name="black">
                <color rgba="0.0 0.0 0.0 1.0"/>
            </material>
        </visual>
        <collision>
            <geometry>
                <cylinder length="0.2" radius="0.15"/>
            </geometry>
        </collision>
    </link>
    <joint name="top_joint" type="fixed">
        <parent link="pillar_link"/>
        <child link="top_link"/>
        <origin xyz="0.0 0.0 0.5" rpy="0.0 0.0 0.0"/>
    </joint>

    <!-- 侧面蓝色小方块 -->
    <link name="blue_block_link">
        <inertial>
            <mass value="0.1"/>
            <inertia ixx="0.01" ixy="0.0" ixz="0.0" iyy="0.01" iyz="0.0" izz="0.01"/>
        </inertial>
        <visual>
            <geometry>
                <box size="0.1 0.1 0.1"/>
            </geometry>
            <material name="blue">
                <color rgba="0.0 0.0 1.0 1.0"/>
            </material>
        </visual>
        <collision>
            <geometry>
                <box size="0.1 0.1 0.1"/>
            </geometry>
        </collision>
    </link>
    <joint name="blue_block_joint" type="fixed">
        <parent link="base_link"/>
        <child link="blue_block_link"/>
        <origin xyz="0.2 0.0 0.1" rpy="0.0 0.0 0.0"/>
    </joint>
</robot>